Workbook

Sheet Start Here
A1: AI Security Risk Workbook v3.0
A3: One workbook that holds your organization's AI risk program: who you are and what you own (Org Profile), how tools are classified (Tool Function Mapping), the controls you expect at each risk level (Guardrail Checklist), the intake a requester fills in, the registers you keep (Tool Registry, Exception Tracker), the vendor landscape for picking tools, and the compliance mapping that ties every guardrail to the frameworks you answer to. The companion skill, ai-tool-risk-assessment, reads this workbook and produces one AI Risk Assessment Record per request.
A5: Cream cells | B5: Yours to fill in or change. Many arrive with a starter value; change only what differs at your organization.
A6: Rose cells | B6: Do not edit. Column A holds the keys the skill reads, and the other rose cells are calculated.
A7: Risk and family colors | B7: Low is sage green, Medium pale yellow, High apricot, Severe terracotta. Each of the seven families keeps one muted hue across every tab. Agentic rows are lavender.
A8: Data classes | B8: Four data classes, fixed across the workbook: Public (Low), Internal (Medium), Confidential (High), Restricted (Severe: PII, PHI, payment, export-controlled or other regulated data, and data about minors). Used as written on the intake, the registry and every record.
A10: 1. The tabs
A11: # | B11: Tab | C11: What it holds | D11: When you use it
A12: 1 | B12: =HYPERLINK("#'Org Profile'!A1","Org Profile") -> Org Profile | C12: Who you are, your governance routing, the tools you own (one or more per family), the program rules every tool is held to, how records look | D12: Fill it in once. Every record reads it.
A13: 2 | B13: =HYPERLINK("#'Tool Function Mapping'!A1","Tool Function Mapping") -> Tool Function Mapping | C13: The seven risk factors with their four levels, and 57 functions mapped to a risk level, the agentic flag, the guardrails each function requires and their families | D13: Classify a tool and list its functions; the functions decide the guardrails. Add functions of your own at the bottom.
A14: 3 | B14: =HYPERLINK("#'Guardrail Checklist'!A1","Guardrail Checklist") -> Guardrail Checklist | C14: 65 guardrails across seven families, each with the rule that puts it in scope (every tool, vendor products, or the functions that name it), the agentic flag, what to verify, what evidence proves it, and the control of yours that meets it | D14: The control library. The record lists the required guardrails at issue with their owner and control; the Verification sheet checks them after deployment.
A15: 4 | B15: =HYPERLINK("#'Intake Form'!A1","Intake Form") -> Intake Form | C15: A request form that is multiple choice wherever the answer has a fixed shape: the tool, how it will be used, vendor documents, and the questions an internal build has to answer | D15: Copy it per request, or hand out the standalone file.
A16: 5 | B16: =HYPERLINK("#'Tool Registry'!A1","Tool Registry") -> Tool Registry | C16: Living inventory of AI tools with risk, owners, status and review dates | D16: Keep it current. Never delete a row; mark it Decommissioned.
A17: 6 | B17: =HYPERLINK("#'Exception Tracker'!A1","Exception Tracker") -> Exception Tracker | C17: Exceptions for Severe-risk tools, guardrail deviations, emergency use, pilots and model versions, with renewals | D17: Whenever a tool runs outside policy for a time.
A18: 7 | B18: =HYPERLINK("#'AI Security Tool Landscape'!A1","AI Security Tool Landscape") -> AI Security Tool Landscape | C18: The seven families and about 100 vendors mapped to primary, secondary and tertiary families, refreshed October 2026 | D18: Picking a tool for a family you have no coverage in. A showcase, not a shortlist.
A19: 8 | B19: =HYPERLINK("#'Compliance Mapping'!A1","Compliance Mapping") -> Compliance Mapping | C19: Every guardrail mapped to CSA AICM, the EU AI Act, ISO/IEC 42001, MITRE ATLAS, NIST AI RMF, NIST AI 600-1, OWASP and SOC 2 | D19: Audit evidence, and the citations the Verification sheet carries.
A21: 2. How a request runs
A22: Step | B22: What happens
A23: 1. Intake | B23: The requester fills the Intake Form, or answers the same questions in chat. The tool name and the kind of request are the only required answers.
A24: 2. Research or discovery | B24: A vendor product is researched from its trust center, ISO/IEC 42001 certificate, AI terms, DPA and documentation. A vendor adding AI to a product you already use starts from the existing registry entry and what changed. An internal build has no public pages, so the engineering owner answers section 4 of the intake.
A25: 3. Classify and threat model | B25: Score the seven risk factors on the Tool Function Mapping tab. The highest factor sets the level. Any autonomous action sets the agentic flag. List the functions the tool performs. Walk STRIDE and the lethal trifecta against the tool.
A26: 4. Required guardrails | B26: The required list is the union of what the tool's functions require, plus the Guardrail Checklist rows marked Every tool (the program's own steps) and, for anything bought, Vendor products. The risk level routes the decision; it does not add guardrails. Each line carries its owner (the vendor, you, or both) and the control that meets it: the vendor's feature or your own tool from Org Profile section 3 and the Guardrail Checklist tab. A guardrail nothing meets is a Gap, and every Gap is a finding.
A27: 5. Issue and decide | B27: The record is issued with its open items (gaps, unknowns, findings due before a decision, questions outstanding) and a blank decision block. It drafts up to four questions for the vendor or the requester, only where an answer would move a risk factor. The approver the Org Profile names for the level records the decision, its conditions and the risk acceptance in the record itself.
A28: 6. Register | B28: The approved tool goes on the Tool Registry with its review cadence. Anything running outside policy goes on the Exception Tracker.
A29: 7. Verify after deployment | B29: Once the tool is live, the verifier walks the Verification sheet in the record file, collects the evidence for each required guardrail and marks Pass or Fail. Security approved the tool with guardrails; this is where it confirms they were put in place.
A31: 3. Risk levels at a glance
A32: Read from Org Profile section 2. Change them there.
A33: Risk level | B33: Approved by | C33: Reviewed | D33: Residual risk accepted by
A34: Low | B34: ='Org Profile'!C28 -> Security reviewer | C34: ='Org Profile'!C32 -> Yearly | D34: ='Org Profile'!C36 -> The business owner of the use case
A35: Medium | B35: ='Org Profile'!C29 -> Department lead with security review | C35: ='Org Profile'!C33 -> Every six months | D35: ='Org Profile'!C36 -> The business owner of the use case
A36: High | B36: ='Org Profile'!C30 -> AI governance committee | C36: ='Org Profile'!C34 -> Quarterly | D36: ='Org Profile'!C37 -> The business unit head
A37: Severe | B37: ='Org Profile'!C31 -> Exception only: CISO and the committee, with an executive sponsor | C37: ='Org Profile'!C35 -> Monthly | D37: ='Org Profile'!C38 -> A named executive, with the exception on record
A39: 4. Version history
A40: Version | B40: Date | C40: Changes
A41: v3.0 | B41: 2026-10-14 | C41: Rebuilt in the program-workbook layout: Org Profile with keys the skill reads, the function and guardrail libraries as tables, a multiple-choice intake that handles vendor products, vendor-added AI and internal builds, the registry and exception tracker kept with small updates, a refreshed landscape (about 100 vendors, statuses through September 2026), and a compliance mapping of every guardrail to eight framework columns with no blank cells. Four fixed data classes. One or more tools per guardrail. Guardrails are required by the functions a tool performs, plus a short every-tool baseline, rather than by risk level. Added two agentic guardrails (agent behavior monitoring, agent memory protection). Records are issued as the security team's assessment with a blank decision block for the approver, list required guardrails with owner, status and control, map the organization's tools against the tool's functions, and carry a Verification sheet for the manual check after deployment and a Coverage data sheet for the program metrics. Program Metrics, User Guide and Governance Guide retired; their settings moved into Org Profile.
A42: v2.0 | B42: 2026-04-23 | C42: 57 functions, 63 guardrails with agentic dual-tagging, 88 vendors, 21 compliance frameworks, muted palette.
A43: v1.3 | B43: 2026-02 | C43: 17 new vendors, 6 agentic guardrails, 4 new functions, updated mappings.
A44: v1.0 | B44: 2025-01 | C44: Initial release: 58 vendors, 40 guardrails, 41 functions.
A46: Last updated 2026-10-14. Owner: your security and risk function (edit on the Org Profile tab). Copyright 2026 Jason Robbins. Licensed under the Apache License, Version 2.0; the LICENSE and NOTICE files travel with the workbook. Vendor and product names identify products and do not imply endorsement.

Sheet Org Profile
A1: AI Security Risk Workbook: Org Profile
A3: Start here. This tab is what makes every assessment yours: your context, your routing, the tools you already own and the rules every new tool is held to. Fill it in once and keep it current. The skill reads it by the keys in column A, never by position, so you can add rows and reorder sections.
A5: Cream cells | B5: Yours to fill in. Pick from the list where a cell has one, and write None or Unknown where that is the honest answer.
A6: Rose cells | B6: Do not edit. Column A holds the keys the skill reads. Copy the key when you add a row of the same kind.
A7: Completion | B7: =IF((58-COUNTA(C11,C12,C13,C14,C15,C16,C17,C18,C19,C24,C25,C26,C27,C28,C29,C30,C31,C32,C33,C34,C35,C36,C37,C38,C39,C40,C41,C42,C43,C44,C45,C46,C51,C52,C53,C54,C55,C56,C57,C58,C59,C60,C61,C62,C63,C64,C65,C66,C67,C68,C69,C74,C75,C76,C77,C78,C83,C84))=0,"Complete: every answer the skill needs is filled in.","Still open: "&(58-COUNTA(C11,C12,C13,C14,C15,C16,C17,C18,C19,C24,C25,C26,C27,C28,C29,C30,C31,C32,C33,C34,C35,C36,C37,C38,C39,C40,C41,C42,C43,C44,C45,C46,C51,C52,C53,C54,C55,C56,C57,C58,C59,C60,C61,C62,C63,C64,C65,C66,C67,C68,C69,C74,C75,C76,C77,C78,C83,C84))&" of 58 answers. The skill stops and asks for them before it assesses anything. Section 6 has working defaults.") -> Still open: 36 of 58 answers. The skill stops and asks for them before it assesses anything. Section 6 has working defaults.
A9: 1. Scope of this workbook
A10: Key | B10: Field | C10: Your answer | D10: How to answer | E10: Example
A11: org.name | B11: Organization or business unit this workbook covers | D11: One workbook per program. Where a business unit runs its own AI program with different rules, give it its own copy. | E11: Northfield Health, corporate IT
A12: org.industry | B12: Industry | D12: Sets the regulatory context the skill reads AI evidence against. | E12: Healthcare delivery
A13: org.regulators | B13: Regulations and contracts that bear on your AI use | D13: Comma-separated. Write None if nothing applies. The skill cites these when a gap touches a regulated requirement. | E13: HIPAA, state privacy law, EU AI Act as a deployer
A14: org.frameworks | B14: Frameworks you report or certify against | D14: Pick from the eight columns on the Compliance Mapping tab: CSA AICM, EU AI Act, ISO/IEC 42001, MITRE ATLAS, NIST AI RMF, NIST AI 600-1, OWASP, SOC 2. Comma-separated. The Verification sheet of every record cites these and leaves the others out. | E14: SOC 2, NIST AI RMF, ISO/IEC 42001
A15: org.customer_commitments | B15: Customer contract commitments that bear on AI | D15: No AI training on client data, residency, notice windows, audit rights. Write None if nothing applies. What you owe your customers, you need from the tools that touch their data. | E15: No AI training on client data; US-only processing
A16: org.scope_boundary | B16: What this program covers | D16: Name the boundary so nobody assumes coverage that is not there. | E16: Every AI tool, feature and agent staff or systems use
A17: org.scope_notes | B17: What sits outside the boundary, and who accepted that | D17: Consumer AI on personal devices, AI features in SaaS the business buys on a card, research use. Say who signed. | E17: Consumer AI on personal devices is out. Accepted by the CIO, March 2026.
A18: org.ai_policy | B18: AI acceptable-use policy | D18: The policy every approval is checked against. | E18: Published
A19: org.ai_policy_location | B19: Where the policy lives | D19: A link or a document name. Write None if there is no policy yet. | E19: Policy portal, AI-AUP-001
A21: 2. Governance and routing
A22: Every row arrives with a starter value. Change what differs at your organization. The quick references on the Start Here, Tool Function Mapping and Tool Registry tabs read these cells, so there is one place to change each thing.
A23: Key | B23: Field | C23: Your answer | D23: How to answer | E23: Example
A24: gov.owner | B24: AI governance program owner (name or role) | D24: If there is none yet, say who is covering. | E24: Director of Security Governance
A25: gov.sponsor | B25: Executive sponsor | D25: The person who would chair a governance review. | E25: CISO
A26: gov.committee | B26: Standing AI governance committee or review board | D26: Yes only if it meets on a cadence and records decisions. | E26: Yes
A27: gov.committee_members | B27: What it is called and who sits on it | D27: Roles are enough. | E27: AI Review Board: CISO, CIO, Privacy, Legal, Data, Engineering
A28: gov.approve_low | B28: Who approves a Low-risk tool | C28: Security reviewer | D28: Standard approval. One person, usually the reviewer who ran the assessment. | E28: Security reviewer
A29: gov.approve_medium | B29: Who approves a Medium-risk tool | C29: Department lead with security review | E29: Department lead with security review
A30: gov.approve_high | B30: Who approves a High-risk tool | C30: AI governance committee | E30: AI governance committee
A31: gov.approve_severe | B31: Who approves a Severe-risk tool | C31: Exception only: CISO and the committee, with an executive sponsor | D31: Severe-risk tools are prohibited by default. An exception is time-bounded and tracked on the Exception Tracker tab. | E31: Exception only: CISO and the committee, with an executive sponsor
A32: gov.review_low | B32: How often a Low-risk tool is reviewed | C32: Yearly | E32: Yearly
A33: gov.review_medium | B33: How often a Medium-risk tool is reviewed | C33: Every six months | E33: Every six months
A34: gov.review_high | B34: How often a High-risk tool is reviewed | C34: Quarterly | E34: Quarterly
A35: gov.review_severe | B35: How often a Severe-risk tool is reviewed | C35: Monthly | E35: Monthly
A36: gov.accept_low | B36: Who accepts residual risk at Low and Medium | C36: The business owner of the use case | D36: Acceptance belongs to someone who owns both the value and the loss. The record names the role, never a reviewer. | E36: The business owner of the use case
A37: gov.accept_high | B37: Who accepts residual risk at High | C37: The business unit head | E37: The business unit head
A38: gov.accept_severe | B38: Who accepts residual risk at Severe | C38: A named executive, with the exception on record | E38: A named executive, with the exception on record
A39: gov.exception_approver | B39: Who approves exceptions to your own AI policy or standard | C39: CISO | D39: An exception is a recorded, temporary departure from your own policy, usually with compensating controls. A different role from the one that accepts risk. | E39: CISO
A40: gov.reviewer | B40: Who signs that an assessment is complete | D40: The security function confirming the work was done at the depth required. Separate from accepting risk. | E40: AI security lead
A41: gov.verifier | B41: Who verifies the guardrails after deployment | D41: The person or team that walks the Verification sheet once the tool is live, collects the evidence and marks Pass or Fail. | E41: Security engineering
A42: gov.human_check | B42: Who checks an AI-drafted record before it counts | D42: A named role. The check covers the evidence and the factor scores, not only the conclusion. | E42: Director of Security Governance
A43: gov.triage_by | B43: Who answers intake questions about a tool | C43: The requester | D43: The requester is the usual answer: the person asking for the tool, who knows how it will be used. For an internal build, the engineering owner answers the build questions. | E43: The requester
A44: gov.risk_appetite | B44: Documented AI risk appetite or tolerance statement | C44: None | D44: Where one exists, acceptances are judged against it. Most organizations have none, which makes every acceptance a judgment call. Write None. | E44: None
...

Sheet Tool Function Mapping
A1: AI Security Risk Workbook: Tool Function Mapping
A3: Classify a tool by the seven risk factors, then list every function it performs. Each function rolls up to a risk level, the agentic flag, the guardrails it requires and the families those guardrails live in. The skill reads both tables by the keys in column A.
A5: Cream cells | B5: The factor wording, the function rows and the three blank rows at the bottom are yours to change or add to.
A6: Rose cells | B6: Keys the skill reads, and the routing quick reference calculated from Org Profile.
A8: 1. Risk classification criteria
A9: Score each factor. The highest-rated factor sets the overall risk level. Agent autonomy drives the agentic flag: anything above "no autonomy" picks up every agentic guardrail whatever the level. Reword a level to fit your environment; keep the four names.
A10: table:risk.factors | B10: Risk factor | C10: Low | D10: Medium | E10: High | G10: Severe
A11: risk.factors | B11: Data sensitivity | C11: Public: information anyone may see | D11: Internal: company information that is not sensitive | E11: Confidential: trade secrets, IP, internal strategy, customer business data | G11: Restricted: PII, PHI, payment, export-controlled or other regulated data; data about minors
A12: risk.factors | B12: Access permissions | C12: Read-only, scoped | D12: Limited write to scoped resources | E12: Full read and write on production resources | G12: Admin, root or infrastructure control
A13: risk.factors | B13: Integration depth | C13: Isolated, no integrations | D13: Limited API, rate-capped | E13: Direct system access: database, filesystem, connectors | G13: Privileged control plane: IAM, secrets, infrastructure
A14: risk.factors | B14: Action reversibility | C14: Read-only, no state change | D14: Reversible writes: edit a document, retry a task | E14: Hard to reverse: send an email, trigger a payment | G14: Irreversible: delete records, post publicly, move money
A15: risk.factors | B15: Data persistence | C15: None, ephemeral | D15: Session only, cleared on close | E15: Cached or stored, TTL-bounded, user-owned | G15: Vendor retains and may train; memory shared across users
A16: risk.factors | B16: External access | C16: None, internal only | D16: Allowlisted endpoints, logged | E16: Broad internet with logged egress | G16: Unrestricted or unlogged egress
A17: risk.factors | B17: Agent autonomy | C17: No autonomy: a person prompts each action | D17: Scoped autonomy with a person approving every write | E17: Autonomous within an allowlist; a person approves Severe actions only | G17: Fully autonomous, no human gate, may spawn sub-agents
A18: Scoring rule: the highest rating across any factor sets the overall risk level. A tool whose agent autonomy sits above the Org Profile ceiling is routed as Severe.
A20: 2. Routing quick reference
A21: Calculated from Org Profile section 2. Change it there.
A22: Risk level | B22: Approved by | E22: Reviewed | G22: Residual risk accepted by
A23: Low | B23: ='Org Profile'!C28 -> Security reviewer | E23: ='Org Profile'!C32 -> Yearly | G23: ='Org Profile'!C36 -> The business owner of the use case
A24: Medium | B24: ='Org Profile'!C29 -> Department lead with security review | E24: ='Org Profile'!C33 -> Every six months | G24: ='Org Profile'!C36 -> The business owner of the use case
A25: High | B25: ='Org Profile'!C30 -> AI governance committee | E25: ='Org Profile'!C34 -> Quarterly | G25: ='Org Profile'!C37 -> The business unit head
A26: Severe | B26: ='Org Profile'!C31 -> Exception only: CISO and the committee, with an executive sponsor | E26: ='Org Profile'!C35 -> Monthly | G26: ='Org Profile'!C38 -> A named executive, with the exception on record
A28: 3. Function to guardrails to families
A29: Identify every function the tool performs; the union of their guardrails, plus the Every tool and Vendor products rows on the Guardrail Checklist, is the tool's required list. Nearly every tool performs the two text functions (LLM prompt processing and AI response generation), which carry the controls any model-backed tool needs; the other functions carry what is specific to them. "Required guardrails" is what a person reads and "Guardrail IDs" is what the skill reads; both come from the Guardrail Checklist, so edit the IDs and the names follow. "Example products" come from the AI Security Tool Landscape; in your own records the skill names the tool you own for each family from Org Profile section 3. Set Active to Off to drop a function, and add your own in the blank rows.
A30: table:functions | B30: Function | C30: Risk | D30: Agentic? | E30: Required guardrails | F30: Guardrail IDs | G30: Families | H30: Example products | I30: Active
A31: functions | B31: Time, date and timezone calculations | C31: Low | D31: No | E31: audit logging | F31: OBS-01 | G31: Observability | I31: On
A32: functions | B32: Public data lookups (weather, rates, reference APIs) | C32: Low | D32: No | E32: rate limiting (per user); domain restrictions (egress); audit logging | F32: RUN-03; RUN-07; OBS-01 | G32: Runtime, Observability | I32: On
A33: functions | B33: Geographic and mapping information | C33: Low | D33: No | E33: pII detection; domain restrictions (egress); audit logging | F33: DAT-02; RUN-07; OBS-01 | G33: Data Protection, Runtime, Observability | I33: On
A34: functions | B34: Basic system health checks (read-only) | C34: Low | D34: No | E34: service account scoping; secrets management; audit logging | F34: NHI-01; NHI-02; OBS-01 | G34: NHI, Observability | H34: Datadog, Arize | I34: On
A35: functions | B35: Static file read (public or non-sensitive) | C35: Low | D35: No | E35: service account scoping; data classification; audit logging | F35: NHI-01; DAT-03; OBS-01 | G35: NHI, Data Protection, Observability | I35: On
A36: functions | B36: Online search interfaces | C36: Medium | D36: No | E36: rate limiting (per user); domain restrictions (egress); dLP rules active; audit logging | F36: RUN-03; RUN-07; DAT-01; OBS-01 | G36: Runtime, Data Protection, Observability | H36: Harmonic, Nightfall, Netskope | I36: On
A37: functions | B37: Web data extraction and scraping | C37: Medium | D37: No | E37: domain restrictions (egress); input validation; audit logging; red team and adversarial testing | F37: RUN-07; RUN-01; OBS-01; OBS-06 | G37: Runtime, Observability | H37: Netskope, Zscaler, Island | I37: On
A38: functions | B38: Automated task execution (scoped) | C38: Medium | D38: Yes | E38: agent authentication; intent validation; tool and function authorization; secrets management; short-lived tokens; rate limiting (per workload); alerting configured; agent behavior monitoring; red team and adversarial testing | F38: NHI-05; NHI-06; NHI-07; NHI-02; NHI-04; RUN-04; OBS-04; OBS-08; OBS-06 | G38: NHI, Runtime, Observability | H38: Arthur, Mindgard, Datadog | I38: On
A39: functions | B39: Log processing and event analysis | C39: Medium | D39: No | E39: service account scoping; pII detection; data masking; data classification; audit logging | F39: NHI-01; DAT-02; DAT-06; DAT-03; OBS-01 | G39: NHI, Data Protection, Observability | H39: Datadog, Arize, Splunk | I39: On
A40: functions | B40: Enterprise data queries (read-only) | C40: Medium | D40: No | E40: service account scoping; secrets management; credential rotation; dLP rules active; pII detection; data classification; audit logging; sIEM integration; alerting configured | F40: NHI-01; NHI-02; NHI-03; DAT-01; DAT-02; DAT-03; OBS-01; OBS-03; OBS-04 | G40: NHI, Data Protection, Observability | H40: Cyera, BigID, Knostic | I40: On
A41: functions | B41: Internal documentation retrieval | C41: Medium | D41: No | E41: service account scoping; secrets management; credential rotation; dLP rules active; data classification; audit logging; sIEM integration; alerting configured; vector store security | F41: NHI-01; NHI-02; NHI-03; DAT-01; DAT-03; OBS-01; OBS-03; OBS-04; SUP-10 | G41: NHI, Data Protection, Observability, Supply Chain | H41: Knostic, Cyera, Reco | I41: On
A42: functions | B42: Code repository read access | C42: Medium | D42: No | E42: service account scoping; secrets management; credential rotation; data classification; audit logging | F42: NHI-01; NHI-02; NHI-03; DAT-03; OBS-01 | G42: NHI, Data Protection, Observability | H42: Wiz, Noma, GitGuardian | I42: On
A43: functions | B43: Email, chat and messaging read access | C43: Medium | D43: No | E43: service account scoping; secrets management; credential rotation; dLP rules active; pII detection; data classification; audit logging; sIEM integration; alerting configured | F43: NHI-01; NHI-02; NHI-03; DAT-01; DAT-02; DAT-03; OBS-01; OBS-03; OBS-04 | G43: NHI, Data Protection, Observability | H43: Harmonic, Nightfall, Knostic | I43: On
A44: functions | B44: LLM prompt processing (text) | C44: Medium | D44: No | E44: input validation; rate limiting (per user); content safety; fallback and graceful degradation; audit logging; log retention; user access tracked; usage analytics; model provenance; model version pinning; model rollback procedure; third-party model assessment; system prompt protection; encryption in transit; encryption at rest; retention policies; training data opt-out; incident disclosure to users; data residency review | F44: RUN-01; RUN-03; RUN-05; RUN-09; OBS-01; OBS-02; SHA-03; SHA-04; SUP-01; SUP-02; SUP-03; SUP-08; SUP-11; DAT-04; DAT-05; DAT-07; DAT-08; DAT-10; POS-08 | G44: Runtime, Observability, Shadow AI, Supply Chain, Data Protection, Posture | H44: Arthur, Mindgard, Prompt Armor, Lakera (Check Point) | I44: On
A45: functions | B45: Multi-modal input processing (image, audio, video) | C45: Medium | D45: No | E45: multi-modal input validation; content safety; input validation | F45: RUN-06; RUN-05; RUN-01 | G45: Runtime | H45: Lakera (Check Point), Azure AI Content Safety, Google Model Armor | I45: On
...

Sheet Guardrail Checklist
A1: AI Security Risk Workbook: Guardrail Checklist
A3: The control library. A guardrail is required for a tool only when a function the tool performs lists it on the Tool Function Mapping tab, so the record for a drafting assistant and the record for an agent that runs shell commands carry different lists. In scope says which rule applies: Every tool = the program's own steps (register, classify, approve, assign an owner), required whatever the tool does | Vendor products = required for anything bought | By function = required only when a listed function names it; the next column shows which functions do. The risk level routes the decision and sets who approves; it does not add guardrails. The agentic flag marks which guardrails are agent controls; it does not put them in scope either. At issue, the record lists every required guardrail with its owner and the control that meets it. After deployment, the Verification sheet in the record file carries the same rows with their verification criteria and evidence, for a person to mark Pass or Fail.
A5: Cream cells | B5: The wording, In scope, the Agentic flag, Your control and Active are yours. Set Active to Off to drop a guardrail from every record without deleting the row; add your own in the blank rows with the family name spelled as it is here. "Required by functions" is calculated from the Tool Function Mapping tab when the workbook is built.
A6: Rose cells | B6: Keys the skill reads. The ID column is the join to the Tool Function Mapping and Compliance Mapping tabs, so keep IDs stable.
A8: 1. The seven families
A9: Family | C9: What it covers | H9: In one line
A10: AI Posture & Governance (POS) | C10: Inventory, risk classification, approval, policy, vendor and compliance review | H10: What AI is in use, who owns it, whether it was approved and against which rules
A11: Runtime Protection & Guardrails (RUN) | C11: Prompt injection and jailbreak defense, output filtering, content safety, rate and cost limits, egress control | H11: The controls that sit in the request path while the tool runs
A12: Shadow AI & Usage Discovery (SHA) | C12: Finding AI use you did not sanction, tracking who uses what, blocking personal accounts | H12: You cannot govern what you cannot see
A13: Observability & Evaluation (OBS) | C13: Audit logging, retention, SIEM, alerting, drift and hallucination monitoring, red teaming, bias testing, agent behavior monitoring | H13: The evidence that the controls work, and the early warning when they stop working
A14: Data Protection for AI (DAT) | C14: DLP, PII detection, classification, encryption, masking, retention, training opt-out, provenance marking, user disclosure | H14: What data reaches the model, what the model keeps, and what leaves
A15: NHI & Agentic Access (NHI) | C15: Service accounts, secrets, rotation, short-lived tokens, agent identity, intent and tool authorization, spawn limits, autonomy limits, boundaries, sandboxes, memory | H15: Identity is the control plane for agents: what an agent is, what it may call, and how far it may go
A16: AI Supply Chain (SUP) | C16: Model provenance, pinning, rollback, training data lineage and consent, pipeline security, integrity checks, third-party models, plugins and MCP servers, vector stores, system prompts, embeddings, action attestation | H16: Where the model, its data, its tools and its prompts came from, and whether they are still what you reviewed
A18: 2. Guardrails
A19: "Your control" is optional: the tool or mechanism that meets this guardrail at your organization where the family tools on Org Profile section 3 are too coarse, for example HashiCorp Vault on NHI-02 when the NHI family row lists three tools, Microsoft Purview on DAT-02, the Tool Registry tab on POS-01, the AI governance committee on POS-03, or a contract clause on DAT-08. Separate several with commas. Blank means the family tools; the record fills "Control that meets it" from here first, then from the family row. "Active" is the switch: Off drops the guardrail from every record without deleting it.
A20: table:guardrails | B20: ID | C20: Family | D20: Guardrail | E20: In scope | F20: Agentic? | G20: Required by functions | H20: Verification criteria | I20: Evidence artifact | J20: Your control | K20: Active
A21: guardrails | B21: POS-01 | C21: AI Posture & Governance | D21: Tool registration | E21: Every tool | F21: No | G21: Every tool, whatever its functions | H21: The tool has an entry in the Tool Registry with every required field filled in. | I21: Tool Registry row: tool, vendor or builder, source, risk level, owners, status. Exported or linked. | K21: On
A22: guardrails | B22: POS-02 | C22: AI Posture & Governance | D22: Risk classification | E22: Every tool | F22: No | G22: Every tool, whatever its functions | H22: The seven risk factors are scored and the highest factor sets the level. The functions the tool performs are listed. | I22: The assessment record, section 4, with the factor scores and the function list. | K22: On
A23: guardrails | B23: POS-03 | C23: AI Posture & Governance | D23: Approval obtained | E23: Every tool | F23: No | G23: Every tool, whatever its functions | H23: Approval is recorded at the level the Org Profile sets for this risk level, with conditions written down. | I23: Ticket or workflow record of the approval, linked from the Tool Registry. | K23: On
A24: guardrails | B24: POS-04 | C24: AI Posture & Governance | D24: Policy alignment | E24: Every tool | F24: No | G24: Every tool, whatever its functions | H24: The use fits the AI acceptable-use policy and any data handling rules it points to. | I24: Signed acknowledgment from the tool owner, or the policy clause the use falls under. | K24: On
A25: guardrails | B25: POS-05 | C25: AI Posture & Governance | D25: Owner assignment | E25: Every tool | F25: No | G25: Every tool, whatever its functions | H25: A business owner and a technical owner are named, and both know they own it. | I25: Tool Registry: Business Owner and Technical Owner fields filled in. | K25: On
A26: guardrails | B26: POS-06 | C26: AI Posture & Governance | D26: Vendor assessment | E26: Vendor products | F26: No | G26: Every vendor product and vendor-added AI feature | H26: The vendor's security posture has been assessed: a SOC 2 Type II or ISO 27001 certificate reviewed, the DPA read, the AI data-handling terms confirmed. | I26: Vendor risk record: SOC 2 Type II under 12 months old, DPA, AI addendum or equivalent, filed in the evidence store. | K26: On
A27: guardrails | B27: POS-07 | C27: AI Posture & Governance | D27: Compliance mapping | E27: By function | F27: No | G27: 5 functions: HR, financial or PII system access; Model-in-the-loop decision routing; Log analysis containing PII or regulated data; Model fine-tuning with production data; Autonomous decision-making on consequential actions | H27: The tool is mapped to the frameworks the organization answers to, using the Compliance Mapping tab. | I27: Completed framework mapping for this tool, stored in the GRC tool or the evidence store. | K27: On
A28: guardrails | B28: POS-08 | C28: AI Posture & Governance | D28: Data residency review | E28: By function | F28: No | G28: 4 functions: LLM prompt processing (text); Enterprise file indexing and search; RAG with confidential documents; Log analysis containing PII or regulated data | H28: Where prompts, outputs, embeddings and logs are processed and stored is known and fits the residency requirements. | I28: Vendor DPA or architecture note naming the regions, checked against the requirements. | K28: On
A29: guardrails | B29: RUN-01 | C29: Runtime Protection & Guardrails | D29: Input validation | E29: By function | F29: No | G29: 5 functions: Web data extraction and scraping; LLM prompt processing (text); Multi-modal input processing (image, audio, video); RAG with confidential documents; Autonomous web browsing | H29: Prompt injection detection runs on every user-supplied input and on retrieved content before it reaches the model. | I29: Runtime product or gateway configuration showing detection enabled, plus a sample blocked request. | K29: On
A30: guardrails | B30: RUN-02 | C30: Runtime Protection & Guardrails | D30: Output filtering | E30: By function | F30: No | G30: 3 functions: AI response generation (text); Automated messaging and email send; Content generation for external publication | H30: Model outputs pass through content filtering and PII redaction before a person or a downstream system sees them. | I30: Filter rules and a sample blocked or redacted response from the log. | K30: On
A31: guardrails | B31: RUN-03 | C31: Runtime Protection & Guardrails | D31: Rate limiting (per user) | E31: By function | F31: No | G31: 3 functions: Public data lookups (weather, rates, reference APIs); Online search interfaces; LLM prompt processing (text) | H31: Per-user request and token limits are configured and enforced. | I31: API gateway or product configuration with the limit values. | K31: On
A32: guardrails | B32: RUN-04 | C32: Runtime Protection & Guardrails | D32: Rate limiting (per workload) | E32: By function | F32: Yes | G32: 9 functions: Automated task execution (scoped); Prompt chaining and workflow orchestration; MCP server: vendor-signed or verified; Code execution in an ephemeral sandbox; Tool and function calling by AI agents; Sub-agent spawning (bounded); Long-running or background agents; Multi-agent orchestration (autonomous); Agent task delegation or unbounded spawning | H32: Per-workload and per-agent request, token and cost ceilings stop a runaway task. | I32: Gateway quota configuration and the cost alert rule. | K32: On
... A85: guardrails | B85: SUP-13 | C85: AI Supply Chain | D85: Agent action attestation | E85: By function | F85: Yes | G85: 9 functions: Human-in-the-loop approval workflows; Sub-agent spawning (bounded); Privileged system automation (production infrastructure); Unrestricted code execution (no sandbox); Infrastructure automation (Terraform, Kubernetes); Autonomous agent with unrestricted API access; Multi-agent orchestration (autonomous); Agent task delegation or unbounded spawning; Autonomous decision-making on consequential actions | H85: Critical agent actions are signed and attested, so an action can be tied to the agent, the person and the inputs that produced it. | I85: Signed action log and the verification procedure. | K85: On
A86: guardrails
A87: guardrails
A88: guardrails
A89: 65 guardrails: 7 for every tool, 2 for vendor products, 56 by function. 21 flagged agentic. New in v3.0: OBS-08 Agent behavior monitoring and NHI-12 Agent memory protection.

Sheet Intake Form
A1: AI Security Risk Workbook: Intake Form
A3: One form per request, about five minutes. Only the tool name and the kind of request are required. Pick from the list wherever a row has one; Not sure is always an acceptable answer, and the skill fills what public pages can answer. A vendor product gets researched from what the vendor publishes. Something you built has no public pages, so section 4 is where its assessment comes from. Copy this tab per request, or use the standalone AI_Intake_Form.xlsx.
A5: Cream cells | B5: Yours to fill in.
A6: Rose cells | B6: Do not edit. Column A holds the keys the skill reads.
A8: 1. The request
A9: Only the first two rows are required. Pick from the list wherever a row has one; Not sure is always an acceptable answer.
A10: Key | B10: Field | C10: Your answer | D10: How to answer
A11: intake.tool | B11: Tool, product or use case name | D11: Required.
A12: intake.source | B12: Which kind of request this is | D12: Required. It decides how the assessment runs: a vendor product is researched from what the vendor publishes, and an internal build is uncovered from section 4 because nothing about it is public.
A13: intake.vendor | B13: Vendor or builder | D13: The company. For an internal build, write Internal and the team.
A14: intake.website | B14: Website or internal location | D14: Helps the skill find the right company or repository.
A15: intake.requester | B15: Your name and role
A16: intake.business_owner | B16: Business owner of the use case | D16: The person who would decide whether a risk is worth taking.
A17: intake.stage | B17: Where this stands
A18: intake.requested_on | B18: Date of this request | D18: Lets the program measure the time from request to decision.
A20: 2. How it will be used
A21: These map to the seven risk factors.
A22: Key | B22: Field | C22: Your answer | D22: How to answer
A23: intake.purpose | B23: What it will do for you | D23: A sentence is enough.
A24: intake.users | B24: Roughly how many people will use it
A25: intake.exposure | B25: Who can reach it
A26: intake.data_class | B26: Highest data class it will see or hold | D26: Four data classes, fixed across the workbook: Public (Low), Internal (Medium), Confidential (High), Restricted (Severe: PII, PHI, payment, export-controlled or other regulated data, and data about minors).
A27: intake.data_examples | B27: Name the kinds of data | D27: Contracts, tickets, source code, patient notes. A few words.
A28: intake.regulated | B28: Is any of it in scope for a regulator or a customer contract | D28: HIPAA, PCI DSS, a state privacy law, a client security addendum, the EU AI Act.
A29: intake.connects | B29: How it connects to your systems | D29: Pick the deepest one that applies.
A30: intake.actions | B30: What it can do on its own | D30: The agent autonomy factor.
A31: intake.tool_calling | B31: Calls tools, functions or APIs on its own
A32: intake.subagents | B32: Spawns sub-agents or delegates tasks to other agents
A33: intake.long_running | B33: Runs long or in the background without a person watching
A34: intake.computer_use | B34: Controls a screen, mouse or keyboard
A35: intake.memory | B35: Keeps memory or context between sessions
A36: intake.mcp | B36: MCP servers, plugins or extensions it loads
A37: intake.external | B37: Browses the web or calls outside services
A38: intake.training | B38: Is your data used to train or improve models
A40: 3. Vendor products only
A41: Skip for an internal build. For an existing vendor adding AI, answer what you can and fill the last two rows.
A42: Key | B42: Field | C42: Your answer | D42: How to answer
A43: intake.plan | B43: Plan, tier or edition | D43: Controls such as SSO, audit export, data residency and the training opt-out often depend on the plan.
A44: intake.deployment | B44: How it runs
A45: intake.region | B45: Where our data is processed
...

Sheet Tool Registry
A1: AI Security Risk Workbook: Tool Registry
A3: Living inventory of every AI tool, vendor AI feature and internal build. Customize the columns for your organization (budget codes, contract dates, agent counts). Never delete a row: set Status to Decommissioned so the audit trail survives. The sample rows show the shape; replace them with yours.
A6: 1. Quick reference
A7: Read from Org Profile section 2. Change it there.
A8: Risk level | B8: Approved by | E8: Reviewed | G8: Residual risk accepted by
A9: Low | B9: ='Org Profile'!C28 -> Security reviewer | E9: ='Org Profile'!C32 -> Yearly | G9: ='Org Profile'!C36 -> The business owner of the use case
A10: Medium | B10: ='Org Profile'!C29 -> Department lead with security review | E10: ='Org Profile'!C33 -> Every six months | G10: ='Org Profile'!C36 -> The business owner of the use case
A11: High | B11: ='Org Profile'!C30 -> AI governance committee | E11: ='Org Profile'!C34 -> Quarterly | G11: ='Org Profile'!C37 -> The business unit head
A12: Severe | B12: ='Org Profile'!C31 -> Exception only: CISO and the committee, with an executive sponsor | E12: ='Org Profile'!C35 -> Monthly | G12: ='Org Profile'!C38 -> A named executive, with the exception on record
A13: Status legend: Active | Under review | Suspended | Exception | Decommissioned. Source: Vendor product | Vendor-added AI | Internal build.
A15: 2. Tool inventory
A16: Record ID | B16: Tool name | C16: Vendor or builder | D16: Source | E16: Risk | F16: Agentic? | G16: Data class | H16: Functions | I16: Required families | J16: Guardrail status | K16: Business owner | L16: Technical owner | M16: Approved | N16: Last review | O16: Next review | P16: Status | Q16: Exception # | R16: Model or provider | S16: Cost center | T16: Contract expiry | U16: Data residency | V16: Regulatory scope | W16: Annual spend | X16: Notes
A17: AIR-2026-CHATGPT | B17: ChatGPT Enterprise | C17: OpenAI | D17: Vendor product | E17: Medium | F17: No | G17: Internal | H17: Content generation, Q&A | I17: Posture, Runtime, Shadow AI, Observability | J17: In scope: 21 of 21 passed | K17: Marketing | L17: IT Security | M17: 2026-01-15 | N17: 2026-07-15 | O17: 2027-01-15 | P17: Active | R17: OpenAI GPT-5 | S17: MKT-100 | T17: 2027-01-14 | U17: US | V17: SOC 2, ISO 27001 | W17: $100K | X17: SSO through Entra; training opt-out in the agreement
A18: AIR-2026-COPILOT | B18: GitHub Copilot Enterprise | C18: Microsoft | D18: Vendor product | E18: Medium | F18: Yes | G18: Confidential | H18: Code generation, code review, coding agent | I18: Posture, Runtime, Data Protection, NHI, Supply Chain | J18: In scope: 33 of 35 passed; NHI-04 and SUP-09 open | K18: Engineering | L18: DevSecOps | M18: 2025-10-01 | N18: 2026-07-15 | O18: 2027-01-15 | P18: Active | R18: OpenAI and Anthropic models through GitHub | S18: ENG-200 | T18: 2026-09-30 | U18: US and EU | V18: SOC 2 | W18: $480K | X18: Content exclusions configured; coding agent limited to pull requests
A19: AIR-2026-CLAUDE | B19: Claude Enterprise | C19: Anthropic | D19: Vendor product | E19: Medium | F19: Yes | G19: Confidential | H19: Content generation, RAG, MCP connectors | I19: Posture, Runtime, Data Protection, NHI, Supply Chain | J19: In scope: 35 of 35 passed | K19: Research | L19: IT Security | M19: 2026-01-20 | N19: 2026-09-15 | O19: 2027-03-15 | P19: Active | R19: Anthropic Claude | S19: R&D-300 | T19: 2027-01-19 | U19: US and EU | V19: SOC 2 | W19: $220K | X19: MCP connector allowlist; memory off for regulated users
A20: AIR-2026-BEDROCK | B20: AWS Bedrock (Claude, Llama) | C20: AWS | D20: Vendor product | E20: High | F20: Yes | G20: Restricted | H20: LLM through API, Bedrock Agents, RAG | I20: All seven families | J20: In scope: 51 of 54 passed; 3 open | K20: Platform Engineering | L20: Cloud Security | M20: 2026-02-10 | N20: 2026-08-10 | O20: 2026-11-10 | P20: Active | R20: Anthropic Claude, Meta Llama through Bedrock | S20: PLAT-400 | T20: Platform | U20: US | V20: SOC 2, ISO 27001, HIPAA-eligible | W20: $1.2M | X20: VPC endpoints only; CloudTrail to the SIEM; customer-managed keys
A21: AIR-2026-CLAIMS | B21: Claims summarization assistant | C21: Internal (Data Science) | D21: Internal build | E21: High | F21: No | G21: Restricted | H21: RAG with confidential documents, AI response generation | I21: Posture, Runtime, Observability, Data Protection, Supply Chain | J21: In scope: 44 of 48 passed; red team scheduled | K21: Claims Operations | L21: ML Platform | M21: 2026-09-01 | N21: 2026-09-01 | O21: 2026-12-01 | P21: Active | R21: Azure OpenAI GPT-5 | S21: DS-500 | T21: Internal | U21: US | V21: HIPAA, SOC 2 | W21: $850K | X21: Vector store need-to-know enforced; evaluation set on file
A22: AIR-2026-OPSAGENT | B22: Operations agent (pilot) | C22: Vendor X | D22: Vendor product | E22: Severe | F22: Yes | G22: Confidential | H22: Task automation, external API calls, RAG | I22: All seven families | J22: In scope: 63 of 65 passed; HITL on every external action | K22: Operations | L22: Security | M22: 2026-06-01 | N22: 2026-09-01 | O22: 2026-10-01 | P22: Exception | Q22: EXC-2026-001 | R22: Vendor-hosted, OpenAI models | S22: OPS-600 | T22: 2026-12-01 | U22: US | V22: SOC 2 | W22: $400K | X22: Monthly review; kill switch tested quarterly
A23: AIR-2026-SLACKMCP | B23: Slack MCP server | C23: Anthropic registry | D23: Vendor product | E23: High | F23: Yes | G23: Internal | H23: Agent tool for Slack read and write | I23: Runtime, NHI, Supply Chain | J23: In scope: 40 of 42 passed | K23: IT Operations | L23: Security Engineering | M23: 2026-03-10 | N23: 2026-09-10 | O23: 2026-12-10 | P23: Active | R23: Not applicable | S23: IT-700 | T23: Not applicable | U23: US | V23: SOC 2 | W23: $0 | X23: Vendor-signed server; scoped to approved channels; per-call authorization
A24: AIR-2026-SFDC-AI | B24: Salesforce Agentforce (added AI feature) | C24: Salesforce | D24: Vendor-added AI | E24: High | F24: Yes | G24: Confidential | H24: Tool calling by AI agents, automated messaging | I24: Posture, Runtime, Data Protection, NHI | J24: In scope: 38 of 44 passed; 6 open | K24: Sales Operations | L24: CRM Platform | M24: 2026-08-20 | N24: 2026-08-20 | O24: 2026-11-20 | P24: Under review | R24: Salesforce Einstein Trust Layer | S24: SALES-250 | T24: 2027-06-30 | U24: US | V24: SOC 2 | W24: Included | X24: Feature was on by default; agent actions limited to drafts pending the open guardrails
A25: AIR-2026-PINECONE | B25: Pinecone (RAG vector store) | C25: Pinecone | D25: Vendor product | E25: High | F25: No | G25: Confidential | H25: Vector database queries, vector database write | I25: Data Protection, Posture, NHI, Supply Chain | J25: In scope: 46 of 48 passed | K25: Data Platform | L25: Cloud Security | M25: 2025-12-15 | N25: 2026-08-20 | O25: 2026-11-20 | P25: Active | R25: Not applicable | S25: DATA-800 | T25: 2026-12-14 | U25: US | V25: SOC 2 | W25: $180K | X25: Private Link; customer-managed keys; no PII in embeddings
A26: AIR-2025-SUPPORTBOT | B26: Legacy support chatbot | C26: Vendor Y | D26: Vendor product | E26: Medium | F26: No | G26: Internal | H26: Q&A on internal documents | I26: Posture, Runtime, Observability | J26: DAT-01 failed at review | K26: Support | L26: IT Operations | M26: 2025-06-01 | N26: 2026-06-01 | O26: 2026-12-01 | P26: Suspended | R26: Vendor-hosted, undisclosed | S26: SUP-900 | T26: 2026-05-31 | U26: US | W26: $24K | X26: DLP rule failed the audit; remediation in progress

Sheet Exception Tracker
A1: AI Security Risk Workbook: Exception Tracker
A3: Track exceptions for Severe-risk tools, guardrail deviations, vendor gaps, compliance gaps, emergency use, model versions and pilots. An exception is a recorded, temporary departure from your own policy, approved by the role Org Profile names (gov.exception_approver), with compensating controls and an expiry. It is not a risk acceptance: acceptance belongs to the business owner the record names.
A6: 1. Exception types
A7: Type | C7: Description | F7: Approval required | I7: Maximum duration | K7: Renewal
A8: Severe tool | C8: A Severe-risk tool approved for use (prohibited by default) | F8: CISO, committee and executive sponsor | I8: 12 months | K8: Required
A9: Guardrail bypass | C9: A required guardrail cannot be implemented yet | F9: Committee | I9: 6 months | K9: Required
A10: Vendor risk | C10: The vendor does not meet the assessment criteria | F10: Committee and Legal | I10: 6 months | K10: Required
A11: Compliance gap | C11: A framework control cannot be satisfied | F11: Committee and Compliance | I11: Until remediated | K11: Review at 90 days
A12: Emergency use | C12: Urgent business need; expedited review | F12: CISO, 48-hour retroactive | I12: 30 days | K12: Convert or close
A13: Model version | C13: A new model version deployed before the full evaluation suite passes | F13: Security and platform lead | I13: 14 days | K13: Convert on evaluation pass
A14: Pilot (agentic or internal build) | C14: An agentic tool or an internal build running with a restricted cohort before full approval | F14: Committee | I14: 60 days | K14: Convert or decommission
A15: Approver of record | C15: ="From Org Profile: "&'Org Profile'!C39&". The approval column above is the starter routing by type; the approver of record signs every exception." -> From Org Profile: CISO. The approval column above is the starter routing by type; the approver of record signs every exception.
A17: 2. Status legend
A18: Active | C18: Exception in effect; compensating controls monitored
A19: Renewal due | C19: Expires within 30 days; renewal required
A20: Expired | C20: Expired; the tool is decommissioned or re-approved
A21: Closed | C21: No longer needed: decommissioned, or converted to standard approval
A22: Rejected | C22: The approver denied the request
A24: 3. Exception log
A25: Exception ID | B25: Record ID | C25: Tool name | D25: Type | E25: Risk | F25: Guardrails affected | G25: Business justification | H25: Compensating controls | I25: Requester | J25: Approvers and vote | K25: Approved | L25: Expires | M25: Renewal | N25: Status | O25: Audit notes | P25: Related incidents
A26: EXC-2026-001 | B26: AIR-2026-OPSAGENT | C26: Operations agent (pilot) | D26: Pilot (agentic or internal build) | E26: Severe | F26: NHI-09 Autonomous action limits, NHI-08 Sub-agent spawn limits | G26: Pilot of an agentic platform for the operations team with a restricted cohort | H26: A person approves every external action; 24/7 monitoring; kill switch tested | I26: P. Lee | J26: CISO, committee 5-0, CTO | K26: 2026-06-01 | L26: 2026-10-01 | M26: Scheduled | N26: Renewal due | O26: Weekly review; convert to standard on pass | P26: None
A27: EXC-2026-002 | B27: AIR-2026-CLAUDE | C27: Claude Enterprise | D27: Model version | E27: Medium | F27: SUP-03 Model rollback procedure | G27: Model upgrade before the full evaluation suite passed; rollback ready | H27: Canary at 5 percent; hourly metrics; rollback runbook tested | I27: P. Lee | J27: Security and platform lead | K27: 2026-03-10 | L27: 2026-03-24 | M27: Converted | N27: Closed | O27: Evaluation suite passed 2026-03-21 | P27: None
A28: EXC-2026-003 | B28: AIR-2026-SFDC-AI | C28: Salesforce Agentforce | D28: Guardrail bypass | E28: High | F28: NHI-07 Tool and function authorization | G28: Vendor feature arrived on by default; tool catalog allowlisting not available at the current plan | H28: Agent actions limited to drafts; weekly log review; upgrade quoted | I28: A. Williams | J28: Committee 4-1 | K28: 2026-08-25 | L28: 2027-02-25 | M28: Pending | N28: Active | O28: Review when the plan upgrade lands | P28: None
A29: EXC-2025-004 | B29: AIR-2025-SUPPORTBOT | C29: Emergency chatbot | D29: Emergency use | E29: Medium | F29: RUN-01 Input validation, RUN-02 Output filtering | G29: Support surge after an outage; needed inside 24 hours | H29: Manual review of flagged conversations for the first 14 days | I29: K. Davis | J29: CISO, 48-hour retroactive | K29: 2025-11-01 | L29: 2025-12-01 | M29: Not applicable | N29: Closed | O29: Converted to standard approval in November 2025 | P29: None
A39: 4. Renewal process
A40: Step | B40: Action | G40: Owner | I40: Timeline
A41: 1 | B41: Submit the renewal with an updated justification | G41: Tool owner | I41: 30 days before expiry
A42: 2 | B42: Verify the compensating controls still work | G42: Security analyst | I42: Within 5 days
A43: 3 | B43: Document any incident during the exception period | G43: Security analyst | I43: With the renewal
A44: 4 | B44: Approver or committee reviews and the vote is recorded | G44: Approver of record | I44: Next scheduled meeting
A45: 5 | B45: Update the exception record with the new dates | G45: Security admin | I45: Within 2 days of the decision
A46: 6 | B46: Tell the requester and the business owner the outcome | G46: Security admin | I46: Same day
A48: 5. Where else this shows up
A49: Org Profile section 2 | C49: Who approves exceptions, who accepts risk, and the review cadence per level
A50: Tool Registry | C50: The Exception # and Record ID columns link the tool to its exception
A51: Guardrail Checklist | C51: Which guardrail is being bypassed, by ID
A52: The assessment record | C52: An exception is proposed in section 8 and routed to the approver of record; it is logged here once granted

Sheet AI Security Tool Landscape
A1: AI Security Risk Workbook: AI Security Tool Landscape
A3: A showcase of the market, not a shortlist. About 100 vendors mapped to the seven families as primary, secondary and tertiary coverage, so you can see overlap and avoid paying twice for the same thing. In your own records the skill names the tools you already own (Org Profile section 3) and points here only for a family with no coverage. Statuses and acquisitions checked against public M&A reporting through September 2026. Vendor positioning changes monthly; confirm before buying. Vendor and product names identify products and do not imply endorsement of, or affiliation with, any vendor.
A6: 1. The seven families
A7: Your tools for each family come from Org Profile section 3. Change them there.
A8: Family | C8: What it covers | G8: Guardrails | H8: Your tools
A9: AI Posture & Governance | C9: Inventory, risk classification, approval, policy, vendor and compliance review | G9: 8 (POS) | H9: ='Org Profile'!C63 -> 0
A10: Runtime Protection & Guardrails | C10: Prompt injection and jailbreak defense, output filtering, content safety, rate and cost limits, egress control | G10: 9 (RUN) | H10: ='Org Profile'!C64 -> 0
A11: Shadow AI & Usage Discovery | C11: Finding AI use you did not sanction, tracking who uses what, blocking personal accounts | G11: 5 (SHA) | H11: ='Org Profile'!C65 -> 0
A12: Observability & Evaluation | C12: Audit logging, retention, SIEM, alerting, drift and hallucination monitoring, red teaming, bias testing, agent behavior monitoring | G12: 8 (OBS) | H12: ='Org Profile'!C66 -> 0
A13: Data Protection for AI | C13: DLP, PII detection, classification, encryption, masking, retention, training opt-out, provenance marking, user disclosure | G13: 10 (DAT) | H13: ='Org Profile'!C67 -> 0
A14: NHI & Agentic Access | C14: Service accounts, secrets, rotation, short-lived tokens, agent identity, intent and tool authorization, spawn limits, autonomy limits, boundaries, sandboxes, memory | G14: 12 (NHI) | H14: ='Org Profile'!C68 -> 0
A15: AI Supply Chain | C15: Model provenance, pinning, rollback, training data lineage and consent, pipeline security, integrity checks, third-party models, plugins and MCP servers, vector stores, system prompts, embeddings, action attestation | G15: 13 (SUP) | H15: ='Org Profile'!C69 -> 0
A17: 2. What changed in 2026
A18: Consolidation kept its pace. Palo Alto Networks closed CyberArk ($25B, February) and added Koi and Portkey to Prisma AIRS. Google closed Wiz ($32B, March). Cisco bought Astrix, Galileo and WideField. Cyera bought Oasis Security (about $1B, July) and became the one vendor that owns both DSPM and agent identity. SailPoint took Entro, Okta took Permiso, 1Password took Apono, Delinea took StrongDM, CrowdStrike took SGNL: every identity platform now has an agent story. Akamai bought LayerX, Proofpoint bought Acuvity, Zscaler bought Symmetry, Varonis bought AllTrue.ai, Fortinet bought Virtue AI, A10 bought TrojAI, Check Point added Cyata and Deepchecks, F5 added SurePath, OpenAI took Promptfoo and Harvey took Guardrails AI. The independents that raised: HiddenLayer ($100M, September), WitnessAI ($58M, January), Harmonic ($50M), Cyera ($400M at $9B). MCP security arrived as a category of its own (Runlayer, Helmet, Operant, plus gateway features from Cloudflare and Microsoft). Before buying a point tool, check whether a platform you already pay for now includes the capability.
A20: 3. Vendor landscape
A21: table:vendors | B21: Vendor (product) | C21: Status | D21: Deployment | E21: Pricing tier | F21: Primary family | G21: Secondary family | H21: Tertiary family | I21: Summary | J21: Best for
A22: vendors | B22: Palo Alto Networks (Prisma AIRS, Protect AI, Portkey, Koi) | C22: Platform | D22: Platform | E22: Enterprise | F22: Runtime Protection & Guardrails | G22: AI Supply Chain | H22: NHI & Agentic Access | I22: Prisma AIRS bundles Protect AI (model scanning, supply chain, red teaming), Portkey (AI gateway, agreed April 2026, roughly $120M to $140M) and Koi (agentic endpoint security, February 2026, about $400M) with CyberArk identity (closed February 2026, $25B). The widest single-vendor AI security stack today. | J22: Palo Alto customers wanting one platform across runtime, supply chain and identity
A23: vendors | B23: Cisco (AI Defense, Robust Intelligence, Astrix, Galileo, WideField) | C23: Platform | D23: Platform | E23: Enterprise | F23: AI Posture & Governance | G23: NHI & Agentic Access | H23: Observability & Evaluation | I23: Cisco AI Defense grew out of Robust Intelligence (2024) and added Astrix non-human identity (May 2026, about $400M), Galileo evaluation and observability (April 2026) and WideField identity threat detection (June 2026). Agent identity and observability land in Splunk and Duo. | J23: Cisco and Splunk shops; agent identity and evaluation under one roof
